I'm sorry, but an uncaught exception occurred.

While running game code:
  File "game/script.rpy", line 229, in script call
    call LB_TEXAS_HOLDEM()
  File "game/script.rpy", line 291, in script call
    call LB_BETTING_ROUND_LOGIC()
  File "game/script.rpy", line 392, in script
    while not POKER_GAME.is_betting_round_over():
  File "game/script.rpy", line 392, in <module>
    while not POKER_GAME.is_betting_round_over():
AttributeError: 'HumanPlayer' object has no attribute 'has_acted_in_round'

-- Full Traceback ------------------------------------------------------------

Full traceback:
  File "game/script.rpy", line 229, in script call
    call LB_TEXAS_HOLDEM()
  File "game/script.rpy", line 291, in script call
    call LB_BETTING_ROUND_LOGIC()
  File "game/script.rpy", line 392, in script
    while not POKER_GAME.is_betting_round_over():
  File "/Volumes/INTERNAL_NVM/Games/RenPy SDK/renpy/ast.py", line 1792, in execute
    if renpy.python.py_eval(self.condition):
  File "/Volumes/INTERNAL_NVM/Games/RenPy SDK/renpy/python.py", line 1209, in py_eval
    return py_eval_bytecode(code, globals, locals)
  File "/Volumes/INTERNAL_NVM/Games/RenPy SDK/renpy/python.py", line 1202, in py_eval_bytecode
    return eval(bytecode, globals, locals)
  File "game/script.rpy", line 392, in <module>
    while not POKER_GAME.is_betting_round_over():
  File "python/classPoker.py", line 593, in is_betting_round_over
AttributeError: 'HumanPlayer' object has no attribute 'has_acted_in_round'

macOS-15.5-arm64-arm-64bit arm64
Ren'Py 8.3.4.24120703
Poker 1.0
Sat Jun 28 19:14:26 2025
